Workbook

Sheet Uitleg
A1: Scrumboard DS2a (designsprint 2, eerste helft): voorbereiding Jira
A2: EVEN NOTITIE: aangezien we in onze sprint EN een keuze willen maken voor concept EN een prototype willen maken referreer ik naar "DS2A" als "DeelSprint 2 A" als in de eerste helft van de sprint.
A3: oh en DS2B als deelsprint 2 B (tweede helft)
A5: Tabbladen
A6: Backlog: alle epics, tickets en sub-tasks (voor de import)
A7: Overzicht: story points + uren per epic, plus de capaciteitscheck voor eerstge heflt van de sprint
A8: Labels: alle labels + waarvoor ze zijn.
A10: Wat moet je invullen?
A11: Gele cellen: de capaciteits-aannames op Overzicht.
A12: Telt mee: op Nee zetten voor werk dat we schrappen of naar de tweeede helft van sprint 2 schuiven; dan klopt het totaal weer.
A13: Schattingen, prioriteit en due dates = voorstellen! Samen aanpassen in de sprintplanning.
A15: Kolommen voor de Jira-import
... A22: Voorbeeld van een ingevulde rij (task)
A23: Ref | B23: Issue Id | C23: Parent Id | D23: Issue Type | E23: Summary | F23: Sprint | G23: Original Estimate (uren) | H23: Priority | I23: Due Date | J23: Assignee | K23: Telt mee
A24: S2-08.2 | B24: (automatisch) | C24: (Issue Id van S2-08) | D24: Task | E24: Interviewguide | F24: DS2a | G24: 2 | H24: Highest | I24: 08-10-2026 | J24: Maryam | K24: Ja
A26: Label "thema-..." op elk ticket = het oude epic-thema (bv. thema-sprint1-afronden). Gebruikt in Overzicht i.p.v. het Epic-veld, voor de capaciteits-rollup per thema, nu Epic weer leeg/anders gebruikt wordt.

Sheet Backlog
A1: Ref | B1: Issue Id | C1: Parent Id | D1: Issue Type | E1: Summary | F1: Description | G1: Epic | H1: Sprint | I1: Story Points | J1: Original Estimate (uren) | K1: Priority | L1: Labels | M1: Due Date | N1: Assignee | O1: Status | P1: Telt mee | Q1: Notitie
A2: S2-01 | B2: 11 | D2: Epic | E2: Onderzoeksplan v1.0 afmaken + inleveren | F2: Waarom: het onderzoeksplan is de basis van alles deze sprint, en de go/no-go van de docent hangt ervan af. Deelvragen, analyse-aanpak, kwaliteitscriteria en risico's zijn al gedaan in v0.6 (2-10); wat overblijft: de open opmerkingen in de andere hoofdstukken, de feedback van stakeholderbijeenkomst 1, en inleveren. Let op: volgens het lesoverzicht sluit het inleveren van de definitieve versie in week 44 (nog navragen bij de docent of dat klopt!). Wij mikken op af vóór de herfstvakantie. Acceptatiecriteria: alle open opmerkingen afgehandeld of bewust geparkeerd; feedback van 1 okt in het feedbacklog met reactie; hoofdvraag compleet; literatuurlijst gevuld; Word-versie = markdown; versie 1.0 ingeleverd. | G2: Onderzoeksplan v1.0 afmaken + inleveren | H2: 2 | I2: 5 | K2: Highest | L2: documentatie op1 op2 op3 thema-sprint1-afronden | M2: 46311 | O2: To Do | P2: Ja
A3: S2-01.1 | B3: 12 | C3: 11 | D3: Task | E3: Feedback feedbacksessie (17-9) + stakeholderbijeenkomst 1 (1-10) in feedbacklog zetten, per punt een reactie | F3: Wat: alle feedback van de feedbacksessie (17-9) en stakeholderbijeenkomst 1 (1-10) in het feedbacklog, per punt: overgenomen / aangepast / geparkeerd + reden. Waarom: feedback telt alleen als zichtbaar is wat we ermee deden (PR4); de notulen van allebei staan nu in de map 28-9 tot 4-10. | G3: Onderzoeksplan v1.0 afmaken + inleveren | H3: 2 | J3: 1.5 | K3: Highest | L3: thema-sprint1-afronden | M3: 46311 | O3: To Do | P3: Ja
A4: S2-01.2 | B4: 13 | C4: 11 | D4: Task | E4: Hoofdvraag afmaken + afstemmen op doelstelling en aantal contactmomenten | F4: Hoofdvraag afmaken en vaststellen; ook checken of hij past bij de doelstelling en de contactmomenten. Waarom: zonder complete hoofdvraag is het plan niet af (OP1). | G4: Onderzoeksplan v1.0 afmaken + inleveren | H4: 2 | J4: 1 | K4: Highest | L4: thema-sprint1-afronden | M4: 46311 | O4: To Do | P4: Ja
A5: S2-01.3 | B5: 14 | C5: 11 | D5: Task | E5: Bronvermelding notulen 23-9 en citaten opdrachtgever in de inleiding | F5: Wat: bij de aanleiding de notulen van 23-9 als bron noemen, ook voor de citaten ("slecht en bagger", "waardeloos") en de Infra-instroom. Waarom: zo is zichtbaar dat we ons baseren op oriënterend onderzoek in het veld (OP1 voldoende). | G5: Onderzoeksplan v1.0 afmaken + inleveren | H5: 2 | J5: 1 | K5: Highest | L5: thema-sprint1-afronden | M5: 46311 | O5: To Do | P5: Ja
A6: S2-01.4 | B6: 15 | C6: 11 | D6: Task | E6: Theoretisch kader uitschrijven | F6: Wat: het theoretisch kader uitschrijven: de begrippen die we gebruiken (bv. doelgroepsegmentatie, co-creatie, AI/ML) met definitie + bron. Waarom: Ik heerinner dat Karlijn er iets over gezegd had, ik weet de details niet meer, dus verbeter deze ticket graag; | G6: Onderzoeksplan v1.0 afmaken + inleveren | H6: 2 | J6: 2 | K6: Highest | L6: thema-sprint1-afronden | M6: 46311 | O6: To Do | P6: Ja
A7: S2-01.5 | B7: 16 | C7: 11 | D7: Task | E7: "3 momenten" in de aanleiding afhandelen | F7: Wat: Bart vroeg of de zin over "3 momenten" moet blijven; samen beslissen (het zijn er eigenlijk 4) en aanpassen. Waarom: open opmerking, en de aanleiding moet kloppen met de rest van het plan. | G7: Onderzoeksplan v1.0 afmaken + inleveren | H7: 2 | J7: 0.5 | K7: Highest | L7: thema-sprint1-afronden | M7: 46311 | O7: To Do | P7: Ja
A8: S2-01.6 | B8: 17 | C8: 11 | D8: Task | E8: Literatuurlijst invullen (alle bronnen uit het plan, APA) | F8: Wat: alle gebruikte bronnen (lesmateriaal, notulen, rubrics, deskresearch) in één stijl in de literatuurlijst. Waarom: de lijst is nu nog leeg, en bronnen moeten controleerbaar zijn. | G8: Onderzoeksplan v1.0 afmaken + inleveren | H8: 2 | J8: 1.5 | K8: Highest | L8: thema-sprint1-afronden | M8: 46311 | O8: To Do | P8: Ja
A9: S2-01.7 | B9: 18 | C9: 11 | D9: Task | E9: Deelvragen toetsen | F9: Wat: de verbeterede deelvragen toetsen voor bruikbaarheid. Waarom: Zonder deelvragen kunnen we de hoofdvraag niet goed beantwoorden | G9: Onderzoeksplan v1.0 afmaken + inleveren | H9: 2 | J9: 1 | K9: Highest | L9: thema-sprint1-afronden | M9: 46311 | O9: To Do | P9: Ja
A10: S2-01.8 | B10: 19 | C10: 11 | D10: Task | E10: Laatste check tegen de rubric onderzoeksplan (OP1–OP3) door een teamgenoot | F10: Wat: iemand die het niet zelf schreef leest het plan na met de rubric onderzoeksplan ernaast (OP1–OP3). Waarom: een frisse blik vangt wat wij missen, en het is meteen "constructief kritisch op andermans werk" (PR2). | G10: Onderzoeksplan v1.0 afmaken + inleveren | H10: 2 | J10: 1 | K10: Highest | L10: thema-sprint1-afronden | M10: 46311 | O10: To Do | P10: Ja
A11: S2-01.9 | B11: 20 | C11: 11 | D11: Task | E11: Navragen bij docent: wanneer + waar inleveren? | F11: Wat: navragen of de definitieve versie in week 44 ingeleverd moet worden (zo staat het in het lesoverzicht), en waar/hoe. Waarom: de deadline is onduidelijk; liever niet gokken! | G11: Onderzoeksplan v1.0 afmaken + inleveren | H11: 2 | J11: 0.5 | K11: Highest | L11: thema-sprint1-afronden | M11: 46311 | O11: To Do | P11: Ja
A12: S2-01.10 | B12: 21 | C12: 11 | D12: Task | E12: Versiebeheer naar 1.0 + inleveren | F12: Wat: versie 1.0 in het versiebeheer zetten en inleveren. Waarom: afronding van het plan; daarna krijgen alleen grotere updates een nieuw versienummer. | G12: Onderzoeksplan v1.0 afmaken + inleveren | H12: 2 | J12: 0.5 | K12: Highest | L12: thema-sprint1-afronden | M12: 46311 | O12: To Do | P12: Ja
A13: S2-02 | B13: 22 | D13: Epic | E13: Sprintreview & retro designsprint 1 vastleggen | F13: Waarom: het resultaat van een sprint = de herformuleerde focus voor de volgende; moet zichtbaar zijn in de DR (design rationale)! (volgens de kickoff, kan het niet in de rubriek vinden :( ) Acceptatiecriteria: DR-blok sprint 1 met sprintdoel, resultaten, waarde voor het doel, retropunten + focus voor sprint 2. | G13: Sprintreview & retro designsprint 1 vastleggen | H13: 2 | I13: 2 | K13: High | L13: proces pr2 del-designrationale thema-sprint1-afronden | M13: 46301 | O13: To Do | P13: Ja
A14: S2-02.1 | B14: 23 | C14: 22 | D14: Task | E14: Retro (start/stop/continue), hele team | F14: Wat: met het hele team terugkijken op sprint 1: waar starten we mee, stoppen we mee, gaan we mee door? Waarom: teamevaluatie hoort bij elke designsprint, en levert verbeterpunten voor DS2a. | G14: Sprintreview & retro designsprint 1 vastleggen | H14: 2 | J14: 4 | K14: High | L14: thema-sprint1-afronden | M14: 46301 | O14: To Do | P14: Ja
A15: S2-02.2 | B15: 24 | C15: 22 | D15: Task | E15: Sprintreview-blok sprint 1 in de DR schrijven | F15: Wat: in de DR een blok voor sprint 1: sprintdoel, resultaten, waarde voor het doel, focus voor sprint 2. Waarom: de DR bouwen we per sprint op, niet pas achteraf. | G15: Sprintreview & retro designsprint 1 vastleggen | H15: 2 | J15: 1.5 | K15: High | L15: thema-sprint1-afronden | M15: 46301 | O15: To Do | P15: Ja
A16: S2-02.3 | B16: 25 | C16: 22 | D16: Task | E16: Retropunten omzetten naar concrete afspraken/tickets | F16: Wat: elk retropunt wordt een afspraak of een ticket. Waarom: anders blijft het bij praten en verandert er niks. | G16: Sprintreview & retro designsprint 1 vastleggen | H16: 2 | J16: 0.5 | K16: High | L16: thema-sprint1-afronden | M16: 46301 | O16: To Do | P16: Ja
A17: S2-03 | B17: 26 | D17: Epic | E17: Openstaande actiepunten opdrachtgever (23-9) afhandelen | F17: Waarom: staan al sinds 23-9 open (oeps); input voor de concepttoets (instroomcijfers) en de bestaande toepassingen (data-games). | G17: Openstaande actiepunten opdrachtgever (23-9) afhandelen | H17: 2 | I17: 2 | K17: Medium | L17: stakeholder pr3 blocked-extern deelvraag-1 thema-sprint1-afronden | M17: 46304 | O17: To Do | P17: Ja
A18: S2-03.1 | B18: 27 | C18: 26 | D18: Task | E18: Instroomcijfers van Arnoud checken: bruikbaar? Meer nodig? | F18: Wat: Arnoud heeft de instroomcijfers al gestuurd; checken of ze bruikbaar zijn voor de analyse (S2-43) en of we nog iets missen. Zo ja: gericht nog opvragen. Waarom: we willen het probleem met cijfers onderbouwen, maar alleen als de data ook echt antwoord geeft op onze vragen. | G18: Openstaande actiepunten opdrachtgever (23-9) afhandelen | H18: 2 | J18: 0.5 | K18: Medium | L18: thema-sprint1-afronden | M18: 46304 | O18: To Do | P18: Ja
A19: S2-03.2 | B19: 28 | C19: 26 | D19: Task | E19: Curriculum-briefing (Teams, dinsdagmiddag) inplannen met opdrachtgever | F19: Wat: een online sessie plannen (bij voorkeur dinsdagmiddag) waarin de opdrachtgever het 2e jaar Data & AI uitlegt. Waarom: input voor deelvraag 1: wat houdt Data & AI eigenlijk in? | G19: Openstaande actiepunten opdrachtgever (23-9) afhandelen | H19: 2 | J19: 0.5 | K19: Medium | L19: thema-sprint1-afronden | M19: 46304 | O19: To Do | P19: Ja
A20: S2-03.3 | B20: 29 | C20: 26 | D20: Task | E20: Contact Erwin Volmering (Lectoraat iWDT) | F20: Wat: contact zoeken met Erwin Volmering van het lectoraat iWDT. Waarom: actiepunt uit het gesprek van 23-9; mogelijk expert/bron voor onze concepten. | G20: Openstaande actiepunten opdrachtgever (23-9) afhandelen | H20: 2 | J20: 0.5 | K20: Medium | L20: thema-sprint1-afronden | M20: 46304 | O20: To Do | P20: Ja
A21: S2-03.4 | B21: 30 | C21: 26 | D21: Task | E21: Bestaande data-games (Aliander, CMD) opvragen | F21: Wat: vragen naar de bestaande data-games die met Aliander en CMD gemaakt zijn. Waarom: input voor de analyse van bestaande toepassingen (S2-04). | G21: Openstaande actiepunten opdrachtgever (23-9) afhandelen | H21: 2 | J21: 0.5 | K21: Medium | L21: thema-sprint1-afronden | M21: 46304 | O21: To Do | P21: Ja
A22: S2-03.5 | B22: 31 | C22: 26 | D22: Task | E22: Curriculum-briefing bijwonen + notulen | F22: Wat: de curriculum-briefing bijwonen en notuleren. Waarom: geeft antwoord op deelvraag 1 en is meteen een bron. | G22: Openstaande actiepunten opdrachtgever (23-9) afhandelen | H22: 2 | J22: 4 | K22: Medium | L22: thema-sprint1-afronden | M22: 46304 | O22: To Do | P22: Ja
A23: S2-04 | B23: 32 | D23: Epic | E23: Analyse bestaande toepassingen | F23: Waarom: de rubric wil dat het plan start vanuit een analyse van een bestaande toepassing, en die missen we nog! Input voor alle drie de concepten (wat werkt wel/niet bij werving?). Acceptatiecriteria: per toepassing: wat is het, wat werkt/werkt niet, welke vraag levert het ons op; staat in het onderzoeksplan. | G23: Analyse bestaande toepassingen | H23: 2 | I23: 5 | K23: High | L23: onderzoek deelvraag-4 op1 et1-kennis concept-algemeen thema-sprint1-afronden | M23: 46309 | O23: To Do | P23: Ja
A24: S2-04.1 | B24: 33 | C24: 32 | D24: Task | E24: 'Hack je gek' (Infra) bekijken/navragen: opzet, waarom werkte het wel voor de instroom? | F24: Wat: uitzoeken hoe 'Hack je gek' van Infra werkt en waarom het daar wél meer instroom gaf. Waarom: een succesvol bestaand voorbeeld; wat kunnen we ervan leren? | G24: Analyse bestaande toepassingen | H24: 2 | J24: 3 | K24: High | L24: thema-sprint1-afronden | M24: 46309 | O24: To Do | P24: Ja
A25: S2-04.2 | B25: 34 | C25: 32 | D25: Task | E25: Huidige Data & AI-workshop analyseren ("waardeloos" volgens opdrachtgever: maar waarom precies?) | F25: Wat: de huidige Data & AI-workshop bekijken en uitzoeken WAAROM die niet werkt. Waarom: zo maken wij niet dezelfde fouten. | G25: Analyse bestaande toepassingen | H25: 2 | J25: 2 | K25: High | L25: thema-sprint1-afronden | M25: 46309 | O25: To Do | P25: Ja
A26: S2-04.3 | B26: 35 | C26: 32 | D26: Task | E26: Data-games Aliander/CMD + 1–2 externe voorbeelden (deskresearch) (als ie er zijn !!) | F26: Wat: de data-games van Aliander/CMD bekijken + 1–2 voorbeelden van buiten de HAN zoeken. Waarom: breder beeld van wat er al bestaat. | G26: Analyse bestaande toepassingen | H26: 2 | J26: 3 | K26: High | L26: thema-sprint1-afronden | M26: 46309 | O26: To Do | P26: Ja
A27: S2-04.4 | B27: 36 | C27: 32 | D27: Task | E27: Analyse uitschrijven in het onderzoeksplan + sources | F27: Wat: de analyse als paragraaf in het onderzoeksplan zetten, met bronnen. Waarom: de rubric wil dat het plan start vanuit een analyse van bestaande toepassingen. | G27: Analyse bestaande toepassingen | H27: 2 | J27: 2 | K27: High | L27: thema-sprint1-afronden | M27: 46309 | O27: To Do | P27: Ja
A28: S2-04.5 | B28: 121 | C28: 32 | D28: Task | E28: Hoe werven andere hogescholen voor Data & AI? (1–2 voorbeelden) | F28: Wat: 1–2 voorbeelden zoeken van hoe andere hogescholen werven voor Data & AI (of vergelijkbare richtingen). Waarom: vraag uit de feedbacksessie (17-9): zijn de ideeën evidence based, en hoe doen andere opleidingen het? | G28: Analyse bestaande toepassingen | H28: 2 | J28: 2 | K28: High | L28: thema-sprint1-afronden | M28: 46309 | O28: To Do | P28: Ja
A29: S2-52 | B29: 118 | D29: Epic | E29: Selectie 48 ideeën → 3 concepten vastleggen in het beslissingenlog | F29: Waarom: vraag uit de feedbacksessie (17-9): "waarom zijn deze drie de beste, waarom zijn de andere 45 afgevallen?" Die keuze staat nu nergens vastgelegd. Acceptatiecriteria: in het beslissingenlog staat hoe we van 48 naar 3 kwamen (criteria, afgevallen ideeën + waarom), met foto's van de brainstorm/crazy eights. | G29: Selectie 48 ideeën → 3 concepten vastleggen in het beslissingenlog | H29: 2 | I29: 1 | K29: Medium | L29: documentatie op1 pr1 thema-sprint1-afronden | M29: 46304 | O29: To Do | P29: Ja
A30: S2-52.1 | B30: 119 | C30: 118 | D30: Task | E30: Foto's van brainstorm/crazy eights verzamelen | F30: Wat: de foto's van de 48 ideeën (brainstorm, crazy eights) bij elkaar zoeken. Waarom: bewijs van het proces, nodig voor het beslissingenlog en de DR. | G30: Selectie 48 ideeën → 3 concepten vastleggen in het beslissingenlog | H30: 2 | J30: 0.5 | K30: Medium | L30: thema-sprint1-afronden | M30: 46304 | O30: To Do | P30: Ja
A31: S2-52.2 | B31: 120 | C31: 118 | D31: Task | E31: Selectiecriteria reconstrueren + in beslissingenlog zetten | F31: Wat: opschrijven op welke criteria we van 48 naar 3 gingen, en welke ideeën afvielen en waarom. Waarom: zo kunnen we de vraag "waarom deze drie?" onderbouwd beantwoorden. | G31: Selectie 48 ideeën → 3 concepten vastleggen in het beslissingenlog | H31: 2 | J31: 1.5 | K31: Medium | L31: thema-sprint1-afronden | M31: 46304 | O31: To Do | P31: Ja
A32: S2-05 | B32: 37 | D32: Epic | E32: Jira omgeving…uhm..klaar maken? Ik weet niet veel, maar ik zet het er voor de zekerheid bij | F32: Waarom: het board zelf zijn we nu al aan het inrichten; wat nog wel moet is vastleggen wanneer een ticket Ready/Done is, zodat iedereen hetzelfde bedoelt met "klaar" (PR2). De toolkeuze in het beslissingenlog zetten is S2-06. | G32: Jira omgeving…uhm..klaar maken? Ik weet niet veel, maar ik zet het er voor de zekerheid bij | H32: 2 | I32: 1 | K32: Highest | L32: proces pr2 thema-proces-jira | M32: 46301 | O32: To Do | P32: Ja
A33: S2-05.3 | B33: 40 | C33: 37 | D33: Task | E33: DoR/DoD en werkafspraken in projectbeschrijving | F33: Wat: de DoR, DoD en werkafspraken in de projectbeschrijving in Jira zetten. Waarom: zo weet iedereen wanneer iets "klaar" is. | G33: Jira omgeving…uhm..klaar maken? Ik weet niet veel, maar ik zet het er voor de zekerheid bij | H33: 2 | J33: 0.5 | K33: Highest | L33: thema-proces-jira | M33: 46301 | O33: To Do | P33: Ja
A34: S2-06 | B34: 42 | D34: Epic | E34: Toolkeuze Jira vastleggen in het beslissingenlog | F34: Waarom: de onderbouwing staat al in Tools-Vergelijking-DTI.md (sectie "Beslissing": Jira + Confluence, 63/90, iedereen heeft er ervaring mee); moet alleen nog als beslissing in het beslissingenlog, met datum + wie besloten heeft. | G34: Toolkeuze Jira vastleggen in het beslissingenlog | H34: 2 | I34: 1 | K34: Medium | L34: proces documentatie pr2 thema-proces-jira | M34: 46304 | O34: To Do | P34: Ja
A35: S2-06.1 | B35: 43 | C35: 42 | D35: Task | E35: Beslissing uit de tools-vergelijking overnemen in het beslissingenlog (+ datum/namen invullen) | F35: Wat: de beslissing uit de tools-vergelijking (Jira + Confluence) in het beslissingenlog zetten, met datum en wie besloten heeft. Waarom: beslissingen tellen alleen als ze vastgelegd zijn, met alternatieven + waarom. | G35: Toolkeuze Jira vastleggen in het beslissingenlog | H35: 2 | J35: 0.5 | K35: Medium | L35: thema-proces-jira | M35: 46304 | O35: To Do | P35: Ja
A36: S2-44 | B36: 49 | D36: Epic | E36: Doelgroep bereiken: testpersonen en toetsmomenten regelen | F36: Waarom: zonder doelgroep kunnen we niks toetsen = grootste risico van de eerste twee weken! Daarom een eigen ticket, zodat je op het board ziet of het geregeld is. Nodig voor de concepttoets (S2-10), de co-creatiesessie (S2-46) en de prototypetest (S2-28). Acceptatiecriteria: overzicht wie / wanneer / waar / hoeveel personen; minimaal één afspraak met eerstejaars en één met scholieren vóór 15 okt. | G36: Doelgroep bereiken: testpersonen en toetsmomenten regelen | H36: 2 | I36: 3 | K36: Highest | L36: onderzoek stakeholder mbo havo-vwo propedeuse blocked-extern pr3 thema-doelgroeponderzoek | M36: 46304 | O36: To Do | P36: Ja
A37: S2-44.1 | B37: 50 | C37: 49 | D37: Task | E37: Excel schoolvoorlichtingen (Teams) doorlopen en aanhaken waar het kan | F37: Wat: in de Excel met schoolvoorlichtingen (Teams) kijken waar we kunnen aanhaken. Waarom: echte scholieren in een echte setting. | G37: Doelgroep bereiken: testpersonen en toetsmomenten regelen | H37: 2 | J37: 1 | K37: Highest | L37: thema-doelgroeponderzoek | M37: 46304 | O37: To Do | P37: Ja
A38: S2-44.2 | B38: 51 | C38: 49 | D38: Task | E38: Eerstejaarsgroep(en) regelen via de opdrachtgever | F38: Wat: via de opdrachtgever een of meer eerstejaarsgroepen regelen. Waarom: eerstejaars zijn makkelijk bereikbaar en ook doelgroep (keuzemoment). | G38: Doelgroep bereiken: testpersonen en toetsmomenten regelen | H38: 2 | J38: 1 | K38: Highest | L38: thema-doelgroeponderzoek | M38: 46304 | O38: To Do | P38: Ja
A39: S2-44.3 | B39: 52 | C39: 49 | D39: Task | E39: Eigen netwerk benaderen (oude school, MBO-contacten, broertjes/zusjes) | F39: Wat: mensen uit ons eigen netwerk benaderen (oude school, MBO-contacten, broertjes/zusjes). Waarom: back-up als de schoolvoorlichtingen niet lukken. | G39: Doelgroep bereiken: testpersonen en toetsmomenten regelen | H39: 2 | J39: 1 | K39: Highest | L39: thema-doelgroeponderzoek | M39: 46304 | O39: To Do | P39: Ja
A40: S2-44.4 | B40: 53 | C40: 49 | D40: Task | E40: Overzicht testpersonen + momenten bijhouden (zonder persoonsgegevens) | F40: Wat: bijhouden wie/wanneer/waar/hoeveel, zonder namen of andere persoonsgegevens. Waarom: overzicht voor het team, en nodig voor de privacy-afspraken. | G40: Doelgroep bereiken: testpersonen en toetsmomenten regelen | H40: 2 | J40: 0.5 | K40: Highest | L40: thema-doelgroeponderzoek | M40: 46304 | O40: To Do | P40: Ja
...

Sheet Overzicht
A1: Overzicht designsprint 2
A2: Alles wordt berekend uit Backlog; alleen rijen met 'Telt mee' = Ja tellen mee.
A4: Epic | B4: Story Points | C4: Uren (sub-tasks)
A5: thema-sprint1-afronden | B5: =SUMIFS(Backlog!$I:$I,Backlog!$L:$L,"*"&$A5&"*",Backlog!$P:$P,"Ja") | C5: =SUMIFS(Backlog!$J:$J,Backlog!$L:$L,"*"&$A5&"*",Backlog!$P:$P,"Ja")
A6: thema-proces-jira | B6: =SUMIFS(Backlog!$I:$I,Backlog!$L:$L,"*"&$A6&"*",Backlog!$P:$P,"Ja") | C6: =SUMIFS(Backlog!$J:$J,Backlog!$L:$L,"*"&$A6&"*",Backlog!$P:$P,"Ja")
A7: thema-doelgroeponderzoek | B7: =SUMIFS(Backlog!$I:$I,Backlog!$L:$L,"*"&$A7&"*",Backlog!$P:$P,"Ja") | C7: =SUMIFS(Backlog!$J:$J,Backlog!$L:$L,"*"&$A7&"*",Backlog!$P:$P,"Ja")
A8: thema-conceptkeuze | B8: =SUMIFS(Backlog!$I:$I,Backlog!$L:$L,"*"&$A8&"*",Backlog!$P:$P,"Ja") | C8: =SUMIFS(Backlog!$J:$J,Backlog!$L:$L,"*"&$A8&"*",Backlog!$P:$P,"Ja")
A9: thema-concept-uitwerken | B9: =SUMIFS(Backlog!$I:$I,Backlog!$L:$L,"*"&$A9&"*",Backlog!$P:$P,"Ja") | C9: =SUMIFS(Backlog!$J:$J,Backlog!$L:$L,"*"&$A9&"*",Backlog!$P:$P,"Ja")
A10: thema-haalbaarheid-prototype | B10: =SUMIFS(Backlog!$I:$I,Backlog!$L:$L,"*"&$A10&"*",Backlog!$P:$P,"Ja") | C10: =SUMIFS(Backlog!$J:$J,Backlog!$L:$L,"*"&$A10&"*",Backlog!$P:$P,"Ja")
A11: thema-ethiek-privacy | B11: =SUMIFS(Backlog!$I:$I,Backlog!$L:$L,"*"&$A11&"*",Backlog!$P:$P,"Ja") | C11: =SUMIFS(Backlog!$J:$J,Backlog!$L:$L,"*"&$A11&"*",Backlog!$P:$P,"Ja")
A12: thema-stakeholders | B12: =SUMIFS(Backlog!$I:$I,Backlog!$L:$L,"*"&$A12&"*",Backlog!$P:$P,"Ja") | C12: =SUMIFS(Backlog!$J:$J,Backlog!$L:$L,"*"&$A12&"*",Backlog!$P:$P,"Ja")
A13: thema-design-rationale | B13: =SUMIFS(Backlog!$I:$I,Backlog!$L:$L,"*"&$A13&"*",Backlog!$P:$P,"Ja") | C13: =SUMIFS(Backlog!$J:$J,Backlog!$L:$L,"*"&$A13&"*",Backlog!$P:$P,"Ja")
A14: thema-beeldmateriaal | B14: =SUMIFS(Backlog!$I:$I,Backlog!$L:$L,"*"&$A14&"*",Backlog!$P:$P,"Ja") | C14: =SUMIFS(Backlog!$J:$J,Backlog!$L:$L,"*"&$A14&"*",Backlog!$P:$P,"Ja")
A15: Totaal | B15: =SUM(B5:B14) | C15: =SUM(C5:C14)
A17: Capaciteit DS2a (gele cellen aanpassen)
A18: Aantal personen | B18: 4 | C18: Teamleden
A19: Projecturen per persoon per week | B19: 16 | C19: Aanname! Nog samen vaststellen (uitgeggaan van din/don)
A20: Buffer-factor | B20: 0.8 | C20: Ruimte voor ziekte, uitloop, onverwachte dingen etc.
A21: Werkweken DS2a | B21: 2 | C21: Week 41 en 42 (ma 5 okt – vr 16 okt)
A22: Beschikbare uren | B22: =B18*B19*B20*B21
A23: Gepland (uren) | B23: =C15
A24: Verschil (negatief = te vol) | B24: =B22-B23 | C24: Ok omdat..you know, er is een tweede helft.)

Sheet Labels
A1: Groep | B1: Labels | C1: Gebruik
A2: Werksoort | B2: onderzoek · ontwerp · prototype · test · documentatie · stakeholder · proces · beeld | C2: Wat voor werk is het?
A3: Deelvraag | B3: deelvraag-1 · deelvraag-2 · deelvraag-3 · deelvraag-4 · deelvraag-5 | C3: Koppeling aan de 5 deelvragen uit het onderzoeksplan (v0.6) = rode draad
A4: Ethiek | B4: ethiek | C4: Ethiek & privacy (eigen hoofdstuk in het plan, geen deelvraag)
A5: Concept | B5: concept-trein · concept-aihuisdier · concept-biometrie · concept-algemeen | C5: Welk concept? (na het beslismoment meteen zichtbaar)
A6: Doelgroep | B6: mbo · havo-vwo · propedeuse | C6: Voor welke doelgroep?
A7: Contactmoment | B7: schoolvoorlichting · open-dag · proefstuderen · keuzemoment | C7: Voor welk contactmoment?
A8: Rubric | B8: pr1 · pr2 · pr3 · pr4 · op1 · op2 · op3 | C8: Welk rubric-criterium bewijst dit ticket? (handig voor de DR!)
A9: Eindterm | B9: et1-kennis · et2-oordeel · et3-communicatie | C9: Dublin-descriptoren
A10: Deliverable | B10: del-designrationale · del-prototype · del-video · del-poster · del-beelden · del-projectbeschrijving | C10: Werk dat direct in een (eind)deliverable komt
A11: Status-extra | B11: blocked-extern · stretch · individueel | C11: Wachten op extern · alleen als er tijd over is · telt individueel
